try:
	raise Exception('1')
finally:
	print(11)
print(2)